Workbook

Sheet Promo Calendar
A1: Retailer | B1: Account | C1: 프로모션명 | D1: 시작일 | E1: 종료일 | F1: 일수 | G1: SKU | H1: MSRP | I1: P1 | J1: P2 | K1: 행사가 (promo price) | L1: 합계 : Qty | M1: 합계 : 거래액 | N1: 합계 : GS | O1: 합계 : NS | P1: Category | Q1: Sub Category | R1: Promo Type | S1: NPD Flag | T1: ActQty | U1: Actual 거래액
A2: =_xlfn.XLOOKUP(B2,Mapping!C:C,Mapping!D:D) -> Costco | B2: Costco | C2: Cyber Monday | D2: 46174 | E2: 46187 | F2: =IF(D2="","",E2-D2+1) -> 14 | G2: BN750KR | I2: 179000 | J2: 179000 | K2: 159000 | L2: 900 | M2: 143100000 | N2: 128880000 | O2: 120502800 | P2: =_xlfn.XLOOKUP(G2,'[1](ST)Product'!$C:$C,'[1](ST)Product'!$E:$E) -> Ninja Motorized | Q2: =_xlfn.XLOOKUP(G2,'[1](ST)Product'!$C:$C,'[1](ST)Product'!$F:$F) -> Trad | R2: Planned | S2: N
A3: =_xlfn.XLOOKUP(B3,Mapping!C:C,Mapping!D:D) -> Coupang | B3: Coupang | C3: 골드박스 | D3: 46174 | E3: 46203 | F3: =IF(D3="","",E3-D3+1) -> 30 | G3: BR201KR | H3: 199900 | I3: 129900 | J3: 129900 | K3: 129900 | L3: 104 | M3: 13509600 | N3: 9579534.5 | O3: 9100557.8 | P3: =_xlfn.XLOOKUP(G3,'[1](ST)Product'!$C:$C,'[1](ST)Product'!$E:$E) -> Ninja Motorized | Q3: =_xlfn.XLOOKUP(G3,'[1](ST)Product'!$C:$C,'[1](ST)Product'!$F:$F) -> Trad | R3: Planned | S3: N
A4: =_xlfn.XLOOKUP(B4,Mapping!C:C,Mapping!D:D) -> Coupang | B4: Coupang | C4: 골드박스 | D4: 46174 | E4: 46203 | F4: =IF(D4="","",E4-D4+1) -> 30 | G4: CS151KRGDAE | H4: 599000 | I4: 399900 | J4: 399900 | K4: 399900 | L4: 200 | M4: 79980000 | N4: 77404909 | O4: 73534664 | P4: =_xlfn.XLOOKUP(G4,'[1](ST)Product'!$C:$C,'[1](ST)Product'!$E:$E) -> Shark Floorcare | Q4: =_xlfn.XLOOKUP(G4,'[1](ST)Product'!$C:$C,'[1](ST)Product'!$F:$F) -> CS | R4: Planned | S4: N
A5: =_xlfn.XLOOKUP(B5,Mapping!C:C,Mapping!D:D) -> Coupang | B5: Coupang | C5: 골드박스 | D5: 46174 | E5: 46203 | F5: =IF(D5="","",E5-D5+1) -> 30 | G5: FN100KRGN1 | H5: 249900 | I5: 219900 | J5: 199900 | K5: 219900 | L5: 0 | M5: 0 | N5: 0 | O5: 0 | P5: =_xlfn.XLOOKUP(G5,'[1](ST)Product'!$C:$C,'[1](ST)Product'!$E:$E) -> Ninja Heated | Q5: =_xlfn.XLOOKUP(G5,'[1](ST)Product'!$C:$C,'[1](ST)Product'!$F:$F) -> Crispi | R5: Planned | S5: Y
A6: =_xlfn.XLOOKUP(B6,Mapping!C:C,Mapping!D:D) -> Coupang | B6: Coupang | C6: 골드박스 | D6: 46174 | E6: 46203 | F6: =IF(D6="","",E6-D6+1) -> 30 | G6: FN100KRGY1 | H6: 249900 | I6: 219900 | J6: 199900 | K6: 219900 | L6: 0 | M6: 0 | N6: 0 | O6: 0 | P6: =_xlfn.XLOOKUP(G6,'[1](ST)Product'!$C:$C,'[1](ST)Product'!$E:$E) -> Ninja Heated | Q6: =_xlfn.XLOOKUP(G6,'[1](ST)Product'!$C:$C,'[1](ST)Product'!$F:$F) -> Crispi | R6: Planned | S6: Y
A7: =_xlfn.XLOOKUP(B7,Mapping!C:C,Mapping!D:D) -> Coupang | B7: Coupang | C7: 골드박스 | D7: 46174 | E7: 46203 | F7: =IF(D7="","",E7-D7+1) -> 30 | G7: FN100KRWH | H7: 249900 | I7: 219900 | J7: 199900 | K7: 219900 | L7: 0 | M7: 0 | N7: 0 | O7: 0 | P7: =_xlfn.XLOOKUP(G7,'[1](ST)Product'!$C:$C,'[1](ST)Product'!$E:$E) -> Ninja Heated | Q7: =_xlfn.XLOOKUP(G7,'[1](ST)Product'!$C:$C,'[1](ST)Product'!$F:$F) -> Crispi | R7: Planned | S7: Y
A8: =_xlfn.XLOOKUP(B8,Mapping!C:C,Mapping!D:D) -> Coupang | B8: Coupang | C8: 골드박스 | D8: 46174 | E8: 46203 | F8: =IF(D8="","",E8-D8+1) -> 30 | G8: FS301KR | H8: 449900 | I8: 379900 | J8: 349900 | K8: 379900 | L8: 0 | M8: 0 | N8: 0 | O8: 0 | P8: =_xlfn.XLOOKUP(G8,'[1](ST)Product'!$C:$C,'[1](ST)Product'!$E:$E) -> Ninja Motorized | Q8: =_xlfn.XLOOKUP(G8,'[1](ST)Product'!$C:$C,'[1](ST)Product'!$F:$F) -> Icecream | R8: Planned | S8: Y
A9: =_xlfn.XLOOKUP(B9,Mapping!C:C,Mapping!D:D) -> Coupang | B9: Coupang | C9: 골드박스 | D9: 46174 | E9: 46203 | F9: =IF(D9="","",E9-D9+1) -> 30 | G9: HD434SLKR | H9: 299900 | I9: 279900 | J9: 249900 | K9: 279900 | L9: 60 | M9: 16794000 | N9: 11908473 | O9: 11313049 | P9: =_xlfn.XLOOKUP(G9,'[1](ST)Product'!$C:$C,'[1](ST)Product'!$E:$E) -> Shark Personal Care | Q9: =_xlfn.XLOOKUP(G9,'[1](ST)Product'!$C:$C,'[1](ST)Product'!$F:$F) -> Flex | R9: Planned | S9: N
A10: =_xlfn.XLOOKUP(B10,Mapping!C:C,Mapping!D:D) -> Coupang | B10: Coupang | C10: 골드박스 | D10: 46174 | E10: 46203 | F10: =IF(D10="","",E10-D10+1) -> 30 | G10: IW4271KRCP | H10: 899000 | I10: 849000 | J10: 799000 | K10: 849000 | L10: 150 | M10: 127350000 | N10: 90302727 | O10: 85787591 | P10: =_xlfn.XLOOKUP(G10,'[1](ST)Product'!$C:$C,'[1](ST)Product'!$E:$E) -> Shark Floorcare | Q10: =_xlfn.XLOOKUP(G10,'[1](ST)Product'!$C:$C,'[1](ST)Product'!$F:$F) -> Kion | R10: Planned | S10: N
A11: =_xlfn.XLOOKUP(B11,Mapping!C:C,Mapping!D:D) -> Coupang | B11: Coupang | C11: 골드박스 | D11: 46174 | E11: 46203 | F11: =IF(D11="","",E11-D11+1) -> 30 | G11: IW5271KRWH | H11: 949000 | I11: 879000 | J11: 849000 | K11: 879000 | L11: 0 | M11: 0 | N11: 0 | O11: 0 | P11: =_xlfn.XLOOKUP(G11,'[1](ST)Product'!$C:$C,'[1](ST)Product'!$E:$E) -> Shark Floorcare | Q11: =_xlfn.XLOOKUP(G11,'[1](ST)Product'!$C:$C,'[1](ST)Product'!$F:$F) -> Kion | R11: Planned | S11: Y
A12: =_xlfn.XLOOKUP(B12,Mapping!C:C,Mapping!D:D) -> Coupang | B12: Coupang | C12: 골드박스 | D12: 46174 | E12: 46203 | F12: =IF(D12="","",E12-D12+1) -> 30 | G12: LC701KRBK | H12: 899000 | I12: 779000 | J12: 779000 | K12: 779000 | L12: 0 | M12: 0 | N12: 0 | O12: 0 | P12: =_xlfn.XLOOKUP(G12,'[1](ST)Product'!$C:$C,'[1](ST)Product'!$E:$E) -> Shark Floorcare | Q12: =_xlfn.XLOOKUP(G12,'[1](ST)Product'!$C:$C,'[1](ST)Product'!$F:$F) -> FW | R12: Planned | S12: N
A13: =_xlfn.XLOOKUP(B13,Mapping!C:C,Mapping!D:D) -> Coupang | B13: Coupang | C13: 골드박스 | D13: 46174 | E13: 46203 | F13: =IF(D13="","",E13-D13+1) -> 30 | G13: LC751KRLV | H13: 899000 | I13: 849000 | J13: 799000 | K13: 849000 | L13: 500 | M13: 424500000 | N13: 3.1873636e+08 | O13: 3.0279955e+08 | P13: =_xlfn.XLOOKUP(G13,'[1](ST)Product'!$C:$C,'[1](ST)Product'!$E:$E) -> Shark Floorcare | Q13: =_xlfn.XLOOKUP(G13,'[1](ST)Product'!$C:$C,'[1](ST)Product'!$F:$F) -> FW | R13: Planned | S13: N
A14: =_xlfn.XLOOKUP(B14,Mapping!C:C,Mapping!D:D) -> Coupang | B14: Coupang | C14: 골드박스 | D14: 46174 | E14: 46203 | F14: =IF(D14="","",E14-D14+1) -> 30 | G14: QX201KR | H14: 329900 | I14: 299900 | J14: 279900 | K14: 299900 | L14: 100 | M14: 29990000 | N14: 23392909 | O14: 22223264 | P14: =_xlfn.XLOOKUP(G14,'[1](ST)Product'!$C:$C,'[1](ST)Product'!$E:$E) -> Ninja Motorized | Q14: =_xlfn.XLOOKUP(G14,'[1](ST)Product'!$C:$C,'[1](ST)Product'!$F:$F) -> Trad | R14: Planned | S14: N
... A32: =_xlfn.XLOOKUP(B32,Mapping!C:C,Mapping!D:D) -> Coupang | B32: Coupang | C32: 골드박스 | D32: 46174 | E32: 46203 | F32: =IF(D32="","",E32-D32+1) -> 30 | G32: HD434BRKR | H32: 299900 | I32: 279900 | J32: 249900 | K32: 279900 | L32: 35 | M32: 9796500 | N32: 6946609.1 | O32: 6599278.6 | P32: =_xlfn.XLOOKUP(G32,'[1](ST)Product'!$C:$C,'[1](ST)Product'!$E:$E) -> Shark Personal Care | Q32: =_xlfn.XLOOKUP(G32,'[1](ST)Product'!$C:$C,'[1](ST)Product'!$F:$F) -> Flex | R32: Planned | S32: N
A33: =_xlfn.XLOOKUP(B33,Mapping!C:C,Mapping!D:D) -> Coupang | B33: Coupang | C33: 골드박스 | D33: 46174 | E33: 46203 | F33: =IF(D33="","",E33-D33+1) -> 30 | G33: BU3521KR | H33: Phased-out | I33: 499000 | J33: 499000 | K33: 499000 | L33: 0 | M33: 0 | N33: 0 | O33: 0 | P33: =_xlfn.XLOOKUP(G33,'[1](ST)Product'!$C:$C,'[1](ST)Product'!$E:$E) -> Shark Floorcare | Q33: =_xlfn.XLOOKUP(G33,'[1](ST)Product'!$C:$C,'[1](ST)Product'!$F:$F) -> Kion | R33: Planned | S33: N
A34: =_xlfn.XLOOKUP(B34,Mapping!C:C,Mapping!D:D) -> Coupang | B34: Coupang | C34: 골드박스 | D34: 46174 | E34: 46203 | F34: =IF(D34="","",E34-D34+1) -> 30 | G34: IW4271KRBK | H34: 899000 | I34: 849000 | J34: 799000 | K34: 849000 | L34: 0 | M34: 0 | N34: 0 | O34: 0 | P34: =_xlfn.XLOOKUP(G34,'[1](ST)Product'!$C:$C,'[1](ST)Product'!$E:$E) -> Shark Floorcare | Q34: =_xlfn.XLOOKUP(G34,'[1](ST)Product'!$C:$C,'[1](ST)Product'!$F:$F) -> Kion | R34: Planned | S34: N
A35: =_xlfn.XLOOKUP(B35,Mapping!C:C,Mapping!D:D) -> Coupang | B35: Coupang | C35: 골드박스 | D35: 46174 | E35: 46203 | F35: =IF(D35="","",E35-D35+1) -> 30 | G35: CI1001KR | H35: 119900 | I35: 109900 | J35: 99900 | K35: 109900 | L35: 30 | M35: 3297000 | N35: 2337872.7 | O35: 2220979.1 | P35: =_xlfn.XLOOKUP(G35,'[1](ST)Product'!$C:$C,'[1](ST)Product'!$E:$E) -> Ninja Motorized | Q35: =_xlfn.XLOOKUP(G35,'[1](ST)Product'!$C:$C,'[1](ST)Product'!$F:$F) -> Hand | R35: Planned | S35: N
A36: =_xlfn.XLOOKUP(B36,Mapping!C:C,Mapping!D:D) -> Coupang | B36: Coupang | C36: 골드박스 | D36: 46174 | E36: 46203 | F36: =IF(D36="","",E36-D36+1) -> 30 | G36: CI100KR | H36: 199900 | I36: 179900 | J36: 159900 | K36: 179900 | L36: 11 | M36: 1978900 | N36: 1403220 | O36: 1333059 | P36: =_xlfn.XLOOKUP(G36,'[1](ST)Product'!$C:$C,'[1](ST)Product'!$E:$E) -> Ninja Motorized | Q36: =_xlfn.XLOOKUP(G36,'[1](ST)Product'!$C:$C,'[1](ST)Product'!$F:$F) -> Hand | R36: Planned | S36: N
A37: =_xlfn.XLOOKUP(B37,Mapping!C:C,Mapping!D:D) -> Coupang | B37: Coupang | C37: 골드박스 | D37: 46174 | E37: 46203 | F37: =IF(D37="","",E37-D37+1) -> 30 | G37: DB351KRSD | H37: 249900 | I37: 229900 | J37: 199900 | K37: 229900 | L37: 0 | M37: 0 | N37: 0 | O37: 0 | P37: =_xlfn.XLOOKUP(G37,'[1](ST)Product'!$C:$C,'[1](ST)Product'!$E:$E) -> Ninja Motorized | Q37: =_xlfn.XLOOKUP(G37,'[1](ST)Product'!$C:$C,'[1](ST)Product'!$F:$F) -> Portable | R37: Planned | S37: Y
A38: =_xlfn.XLOOKUP(B38,Mapping!C:C,Mapping!D:D) -> Coupang | B38: Coupang | C38: 골드박스 | D38: 46174 | E38: 46203 | F38: =IF(D38="","",E38-D38+1) -> 30 | G38: IW5271KRBK | H38: 949000 | I38: 879000 | J38: 849000 | K38: 879000 | L38: 0 | M38: 0 | N38: 0 | O38: 0 | P38: =_xlfn.XLOOKUP(G38,'[1](ST)Product'!$C:$C,'[1](ST)Product'!$E:$E) -> #N/A | Q38: =_xlfn.XLOOKUP(G38,'[1](ST)Product'!$C:$C,'[1](ST)Product'!$F:$F) -> #N/A | R38: Planned | S38: N
A39: =_xlfn.XLOOKUP(B39,Mapping!C:C,Mapping!D:D) -> Coupang | B39: Coupang | C39: 골드박스 | D39: 46174 | E39: 46203 | F39: =IF(D39="","",E39-D39+1) -> 30 | G39: CS150KRAE | H39: 549000 | I39: 399900 | J39: 379900 | K39: 399900 | L39: 0 | M39: 0 | N39: 0 | O39: 0 | P39: =_xlfn.XLOOKUP(G39,'[1](ST)Product'!$C:$C,'[1](ST)Product'!$E:$E) -> Shark Floorcare | Q39: =_xlfn.XLOOKUP(G39,'[1](ST)Product'!$C:$C,'[1](ST)Product'!$F:$F) -> CS | R39: Planned | S39: N
A40: =_xlfn.XLOOKUP(B40,Mapping!C:C,Mapping!D:D) -> Coupang | B40: Coupang | C40: 골드박스 | D40: 46174 | E40: 46203 | F40: =IF(D40="","",E40-D40+1) -> 30 | G40: LC152KRIV | H40: 699000 | I40: 499000 | J40: 499000 | K40: 699000 | L40: 0 | M40: 0 | N40: 0 | O40: 0 | P40: =_xlfn.XLOOKUP(G40,'[1](ST)Product'!$C:$C,'[1](ST)Product'!$E:$E) -> Shark Floorcare | Q40: =_xlfn.XLOOKUP(G40,'[1](ST)Product'!$C:$C,'[1](ST)Product'!$F:$F) -> FW | R40: Planned | S40: Y
A41: =_xlfn.XLOOKUP(B41,Mapping!C:C,Mapping!D:D) -> Coupang | B41: Coupang | C41: 골드박스 | D41: 46174 | E41: 46203 | F41: =IF(D41="","",E41-D41+1) -> 30 | G41: LC156KR | H41: 699000 | I41: 519000 | J41: 519000 | K41: 699000 | L41: 0 | M41: 0 | N41: 0 | O41: 0 | P41: =_xlfn.XLOOKUP(G41,'[1](ST)Product'!$C:$C,'[1](ST)Product'!$E:$E) -> #N/A | Q41: =_xlfn.XLOOKUP(G41,'[1](ST)Product'!$C:$C,'[1](ST)Product'!$F:$F) -> #N/A | R41: Planned | S41: Y
A42: =_xlfn.XLOOKUP(B42,Mapping!C:C,Mapping!D:D) -> Coupang | B42: Coupang | C42: 골드박스 | D42: 46174 | E42: 46203 | F42: =IF(D42="","",E42-D42+1) -> 30 | G42: LC951KRSN | H42: 949000 | I42: 879000 | J42: 849000 | K42: 879000 | L42: 0 | M42: 0 | N42: 0 | O42: 0 | P42: =_xlfn.XLOOKUP(G42,'[1](ST)Product'!$C:$C,'[1](ST)Product'!$E:$E) -> #N/A | Q42: =_xlfn.XLOOKUP(G42,'[1](ST)Product'!$C:$C,'[1](ST)Product'!$F:$F) -> #N/A | R42: Planned | S42: Y
A43: =_xlfn.XLOOKUP(B43,Mapping!C:C,Mapping!D:D) -> Coupang | B43: Coupang | C43: 골드박스 | D43: 46174 | E43: 46203 | F43: =IF(D43="","",E43-D43+1) -> 30 | G43: BU3641KR | H43: 699000 | I43: 499000 | J43: 499000 | K43: 499000 | L43: 0 | M43: 0 | N43: 0 | O43: 0 | P43: =_xlfn.XLOOKUP(G43,'[1](ST)Product'!$C:$C,'[1](ST)Product'!$E:$E) -> Shark Floorcare | Q43: =_xlfn.XLOOKUP(G43,'[1](ST)Product'!$C:$C,'[1](ST)Product'!$F:$F) -> Kion | R43: Planned | S43: Y
A44: =_xlfn.XLOOKUP(B44,Mapping!C:C,Mapping!D:D) -> Coupang | B44: Coupang | C44: 골드박스 | D44: 46174 | E44: 46203 | F44: =IF(D44="","",E44-D44+1) -> 30 | G44: IW3145KR | H44: 799000 | I44: 699000 | J44: 649000 | K44: 699000 | L44: 0 | M44: 0 | N44: 0 | O44: 0 | P44: =_xlfn.XLOOKUP(G44,'[1](ST)Product'!$C:$C,'[1](ST)Product'!$E:$E) -> #N/A | Q44: =_xlfn.XLOOKUP(G44,'[1](ST)Product'!$C:$C,'[1](ST)Product'!$F:$F) -> #N/A | R44: Planned | S44: N
A45: =_xlfn.XLOOKUP(B45,Mapping!C:C,Mapping!D:D) -> Coupang | B45: Coupang | C45: 골드박스 | D45: 46174 | E45: 46203 | F45: =IF(D45="","",E45-D45+1) -> 30 | G45: IW3241KRBK | H45: 849000 | I45: 749000 | J45: 699000 | K45: 749000 | L45: 0 | M45: 0 | N45: 0 | O45: 0 | P45: =_xlfn.XLOOKUP(G45,'[1](ST)Product'!$C:$C,'[1](ST)Product'!$E:$E) -> Shark Floorcare | Q45: =_xlfn.XLOOKUP(G45,'[1](ST)Product'!$C:$C,'[1](ST)Product'!$F:$F) -> Kion | R45: Planned | S45: N
... A53: =_xlfn.XLOOKUP(B53,Mapping!C:C,Mapping!D:D) -> Coupang | B53: Coupang | C53: 골드박스 | D53: 46174 | E53: 46203 | F53: =IF(D53="","",E53-D53+1) -> 30 | G53: DB351KRBL | H53: 249900 | I53: 229900 | J53: 199900 | K53: 229900 | L53: 0 | M53: 0 | N53: 0 | O53: 0 | P53: =_xlfn.XLOOKUP(G53,'[1](ST)Product'!$C:$C,'[1](ST)Product'!$E:$E) -> Ninja Motorized | Q53: =_xlfn.XLOOKUP(G53,'[1](ST)Product'!$C:$C,'[1](ST)Product'!$F:$F) -> Portable | R53: Planned | S53: Y
A54: =_xlfn.XLOOKUP(B54,Mapping!C:C,Mapping!D:D) -> Coupang | B54: Coupang | C54: 골드박스 | D54: 46174 | E54: 46203 | F54: =IF(D54="","",E54-D54+1) -> 30 | G54: CB151KR | H54: Phased-out | I54: 169900 | J54: 149900 | K54: 169900 | L54: 500 | M54: 84950000 | N54: 70873636 | O54: 67329955 | P54: =_xlfn.XLOOKUP(G54,'[1](ST)Product'!$C:$C,'[1](ST)Product'!$E:$E) -> Ninja Motorized | Q54: =_xlfn.XLOOKUP(G54,'[1](ST)Product'!$C:$C,'[1](ST)Product'!$F:$F) -> Trad | R54: Planned | S54: N
A55: =_xlfn.XLOOKUP(B55,Mapping!C:C,Mapping!D:D) -> Coupang | B55: Coupang | C55: 골드박스 | D55: 46174 | E55: 46203 | F55: =IF(D55="","",E55-D55+1) -> 30 | G55: CB350KR | H55: Phased-out | I55: 219900 | J55: 199900 | K55: 219900 | L55: 0 | M55: 0 | N55: 0 | O55: 0 | P55: =_xlfn.XLOOKUP(G55,'[1](ST)Product'!$C:$C,'[1](ST)Product'!$E:$E) -> Ninja Motorized | Q55: =_xlfn.XLOOKUP(G55,'[1](ST)Product'!$C:$C,'[1](ST)Product'!$F:$F) -> Trad | R55: Planned | S55: N
A56: =_xlfn.XLOOKUP(B56,Mapping!C:C,Mapping!D:D) -> Coupang | B56: Coupang | C56: 골드박스 | D56: 46174 | E56: 46203 | F56: =IF(D56="","",E56-D56+1) -> 30 | G56: BL642KR | H56: Phased-out | I56: 224900 | J56: 199900 | K56: 224900 | L56: -1 | M56: -224900 | N56: -159474.55 | O56: -151500.82 | P56: =_xlfn.XLOOKUP(G56,'[1](ST)Product'!$C:$C,'[1](ST)Product'!$E:$E) -> Ninja Motorized | Q56: =_xlfn.XLOOKUP(G56,'[1](ST)Product'!$C:$C,'[1](ST)Product'!$F:$F) -> Trad | R56: Planned | S56: N
A57: =_xlfn.XLOOKUP(B57,Mapping!C:C,Mapping!D:D) -> Coupang | B57: Coupang | C57: 골드박스 | D57: 46174 | E57: 46203 | F57: =IF(D57="","",E57-D57+1) -> 30 | G57: TB301KR | H57: Phased-out | I57: 249900 | J57: 229900 | K57: 249900 | L57: 50 | M57: 12495000 | N57: 10632818 | O57: 10101177 | P57: =_xlfn.XLOOKUP(G57,'[1](ST)Product'!$C:$C,'[1](ST)Product'!$E:$E) -> Ninja Motorized | Q57: =_xlfn.XLOOKUP(G57,'[1](ST)Product'!$C:$C,'[1](ST)Product'!$F:$F) -> Trad | R57: Planned | S57: N
A58: =_xlfn.XLOOKUP(B58,Mapping!C:C,Mapping!D:D) -> Coupang | B58: Coupang | C58: 골드박스 | D58: 46174 | E58: 46203 | F58: =IF(D58="","",E58-D58+1) -> 30 | G58: BL682KR | H58: Phased-out | I58: 289900 | J58: 249900 | K58: 289900 | L58: 0 | M58: 0 | N58: 0 | O58: 0 | P58: =_xlfn.XLOOKUP(G58,'[1](ST)Product'!$C:$C,'[1](ST)Product'!$E:$E) -> Ninja Motorized | Q58: =_xlfn.XLOOKUP(G58,'[1](ST)Product'!$C:$C,'[1](ST)Product'!$F:$F) -> Kitchen | R58: Planned | S58: N
A59: =_xlfn.XLOOKUP(B59,Mapping!C:C,Mapping!D:D) -> Coupang | B59: Coupang | C59: 골드박스 | D59: 46174 | E59: 46203 | F59: =IF(D59="","",E59-D59+1) -> 30 | G59: CI1000KR | H59: 139900 | I59: 129900 | J59: 119900 | K59: 129900 | L59: 0 | M59: 0 | N59: 0 | O59: 0 | P59: =_xlfn.XLOOKUP(G59,'[1](ST)Product'!$C:$C,'[1](ST)Product'!$E:$E) -> Ninja Motorized | Q59: =_xlfn.XLOOKUP(G59,'[1](ST)Product'!$C:$C,'[1](ST)Product'!$F:$F) -> Hand | R59: Planned | S59: N
A60: =_xlfn.XLOOKUP(B60,Mapping!C:C,Mapping!D:D) -> Coupang | B60: Coupang | C60: 골드박스 | D60: 46174 | E60: 46203 | F60: =IF(D60="","",E60-D60+1) -> 30 | G60: FN090KR | H60: 229900 | I60: 189900 | J60: 189900 | K60: 189900 | L60: 0 | M60: 0 | N60: 0 | O60: 0 | P60: =_xlfn.XLOOKUP(G60,'[1](ST)Product'!$C:$C,'[1](ST)Product'!$E:$E) -> Ninja Heated | Q60: =_xlfn.XLOOKUP(G60,'[1](ST)Product'!$C:$C,'[1](ST)Product'!$F:$F) -> Crispi | R60: Planned | S60: Y
A61: =_xlfn.XLOOKUP(B61,Mapping!C:C,Mapping!D:D) -> Coupang | B61: Coupang | C61: 골드박스 | D61: 46174 | E61: 46203 | F61: =IF(D61="","",E61-D61+1) -> 30 | G61: FN100KRSD1 | H61: 249900 | I61: 219900 | J61: 199900 | K61: 219900 | L61: 0 | M61: 0 | N61: 0 | O61: 0 | P61: =_xlfn.XLOOKUP(G61,'[1](ST)Product'!$C:$C,'[1](ST)Product'!$E:$E) -> Ninja Heated | Q61: =_xlfn.XLOOKUP(G61,'[1](ST)Product'!$C:$C,'[1](ST)Product'!$F:$F) -> Crispi | R61: Planned | S61: Y
A62: =_xlfn.XLOOKUP(B62,Mapping!C:C,Mapping!D:D) -> Coupang | B62: Coupang | C62: 골드박스 | D62: 46174 | E62: 46203 | F62: =IF(D62="","",E62-D62+1) -> 30 | G62: FN091KRND | H62: 249900 | I62: 209900 | J62: 189900 | K62: 209900 | L62: 0 | M62: 0 | N62: 0 | O62: 0 | P62: =_xlfn.XLOOKUP(G62,'[1](ST)Product'!$C:$C,'[1](ST)Product'!$E:$E) -> #N/A | Q62: =_xlfn.XLOOKUP(G62,'[1](ST)Product'!$C:$C,'[1](ST)Product'!$F:$F) -> #N/A | R62: Planned | S62: Y
A63: =_xlfn.XLOOKUP(B63,Mapping!C:C,Mapping!D:D) -> Coupang | B63: Coupang | C63: 골드박스 | D63: 46174 | E63: 46203 | F63: =IF(D63="","",E63-D63+1) -> 30 | G63: MC1101KRBK | H63: 199900 | I63: 179900 | J63: 159900 | K63: 179900 | L63: 0 | M63: 0 | N63: 0 | O63: 0 | P63: =_xlfn.XLOOKUP(G63,'[1](ST)Product'!$C:$C,'[1](ST)Product'!$E:$E) -> Ninja Heated | Q63: =_xlfn.XLOOKUP(G63,'[1](ST)Product'!$C:$C,'[1](ST)Product'!$F:$F) -> Multi Cooker | R63: Planned | S63: Y
A64: =_xlfn.XLOOKUP(B64,Mapping!C:C,Mapping!D:D) -> Coupang | B64: Coupang | C64: 골드박스 | D64: 46174 | E64: 46203 | F64: =IF(D64="","",E64-D64+1) -> 30 | G64: MC1105KRIV1 | H64: 199900 | I64: 179900 | J64: 159900 | K64: 179900 | L64: 0 | M64: 0 | N64: 0 | O64: 0 | P64: =_xlfn.XLOOKUP(G64,'[1](ST)Product'!$C:$C,'[1](ST)Product'!$E:$E) -> Ninja Heated | Q64: =_xlfn.XLOOKUP(G64,'[1](ST)Product'!$C:$C,'[1](ST)Product'!$F:$F) -> Multi Cooker | R64: Planned | S64: Y
...

Sheet GB
A1: Date | B1: 프로모션명 | C1: SKU | D1: Unit Sold | E1: Revenue
A2: 46174 | B2: 보드레 | C2: FN100KRGY1 | D2: 1 | E2: 127942
A3: 46174 | B3: 초코홈 | C3: TF200SKR | D3: 1 | E3: 203578
A4: 46174 | B4: 초코홈 | C4: TF200SKR | D4: 1 | E4: 203578
A5: 46174 | B5: 초코홈 | C5: TF200SKR | D5: 1 | E5: 203578
A6: 46174 | B6: 초코홈 | C6: TF200SKR | D6: 1 | E6: 203578
A7: 46174 | B7: 초코홈 | C7: TF200SKR | D7: 1 | E7: 203578
A8: 46174 | B8: 부끄시끄 | C8: FS301KR | D8: 1 | E8: 221033
A9: 46174 | B9: 초코홈 | C9: TF200SKR | D9: 1 | E9: 203578
A10: 46174 | B10: 부끄시끄 | C10: FS301KR | D10: 1 | E10: 221033
A11: 46174 | B11: 초코홈 | C11: TF200SKR | D11: 1 | E11: 203578
A12: 46174 | B12: 초코홈 | C12: TF200SKR | D12: 1 | E12: 203578
A13: 46174 | B13: 초코홈 | C13: TF200SKR | D13: 1 | E13: 203578
... A5683: 46196 | B5683: 메종드마미 | C5683: LC751KRLV | D5683: 1 | E5683: 464873
A5684: 46196 | C5684: BC151KRPR | D5684: 500 | E5684: 22129545
A5685: 46196 | C5685: BC151KRNV | D5685: 2000 | E5685: 88518182
A5686: 46196 | C5686: BC151KRCR | D5686: 1000 | E5686: 44259091
A5687: 46196 | C5687: BC151KREM | D5687: 6500 | E5687: 287684091
A5688: 46197 | B5688: 심플리홈 | C5688: LC751KRLV | D5688: 1 | E5688: 464873
A5689: 46197 | B5689: 보드레 | C5689: AG551KR | D5689: 1 | E5689: 232669
A5690: 46197 | B5690: 해나하우스 | C5690: BC251KRIV | D5690: 1 | E5690: 69760
A5691: 46197 | B5691: 심플리홈 | C5691: LC751KRLV | D5691: 1 | E5691: 464873
A5692: 46197 | B5692: 심플리홈 | C5692: LC751KRLV | D5692: 1 | E5692: 464873
A5693: 46197 | B5693: 심플리홈 | C5693: LC751KRLV | D5693: 1 | E5693: 464873
A5694: 46197 | B5694: 이지웰 | C5694: LC351KRWH | D5694: 1 | E5694: 442591
A5695: 46197 | B5695: 심플리홈 | C5695: LC751KRLV | D5695: 1 | E5695: 464873
A5696: 46197 | B5696: 홈앤홈 | C5696: BC251KRIV | D5696: 1 | E5696: 69760
A5697: 46197 | B5697: 보드레 | C5697: AG551KR | D5697: 1 | E5697: 232669
A5698: 46197 | B5698: 심플리홈 | C5698: LC751KRLV | D5698: 1 | E5698: 464873
A5699: 46197 | B5699: 홈앤홈 | C5699: BC251KRPK | D5699: 1 | E5699: 69760
... A5937: 46197 | B5937: 심플리홈 | C5937: LC751KRLV | D5937: 1 | E5937: 464873
A5938: 46197 | C5938: NJ1001KR | D5938: 10000 | E5938: 209090909
A5939: 46198 | B5939: 리뷰머신 | C5939: TF200SKRWH | D5939: 1 | E5939: 203578
A5940: 46198 | B5940: 초코홈 | C5940: TF200SKRWH | D5940: 1 | E5940: 203578
A5941: 46198 | B5941: 초코홈 | C5941: TF200SKRWH | D5941: 1 | E5941: 203578
A5942: 46198 | B5942: 초코홈 | C5942: TF200SKRWH | D5942: 1 | E5942: 203578
A5943: 46198 | B5943: 초코홈 | C5943: TF200SKRWH | D5943: 1 | E5943: 203578
A5944: 46198 | B5944: 초코홈 | C5944: TF200SKRWH | D5944: 1 | E5944: 203578
A5945: 46198 | B5945: 초코홈 | C5945: TF200SKRWH | D5945: 1 | E5945: 203578
A5946: 46198 | B5946: 이지웰 | C5946: AF181KR | D5946: 1 | E5946: 118123
...

Sheet Mapping
B1: Channel | C1: Account | D1: Mapping | H1: Retailor
B2: Online | C2: Coupang | D2: Coupang | H2: (주)지에스홈쇼핑 _ PP | I2: PP
B3: Online | C3: GB B2B | D3: Group Buying | H3: 씨제이홈쇼핑_ PP | I3: PP
B4: Online | C4: GB B2B2C | D4: Group Buying | H4: 롯데홈쇼핑(우리홈쇼핑) _ TVHS | I4: TVHS
B5: Offline | C5: Himart | D5: HI-MART | H5: 현대홈쇼핑 _ PP | I5: PP
B6: Online | C6: Naver | D6: Naver | H6: 롯데홈쇼핑(우리홈쇼핑) _ PP | I6: PP
B7: TVHS | C7: PP | D7: PP | H7: 현대홈쇼핑 _ TVHS | I7: TVHS
B8: Offline | C8: Costco | D8: Costco | H8: 씨제이홈쇼핑_ TVHS | I8: TVHS
B9: TVHS | C9: TVHS | D9: TVHS | H9: (주)신세계라이브쇼핑 | I9: TVHS
B10: Offline | C10: Emart | D10: E-MART | H10: Cosmo_SSG dept | I10: Dept Store
B11: Offline | C11: Dept | D11: Dept Store | H11: Cosmo_Hyundai dept | I11: Dept Store
B12: Online | C12: Other Online | D12: other Online malls | H12: Cosmo_Lotte dept | I12: Dept Store
B13: Online | C13: (주)이베이코리아(지마켓) | D13: other Online malls | H13: Cosmo_AK dept | I13: Dept Store
... B26: Online | C26: 십일번가 주식회사 | D26: other Online malls | H26: Cosmo_Yowon_B2B | I26: B2B
H27: (주)이베이코리아(지마켓) | I27: other Online malls
H28: 주식회사 29cm | I28: other Online malls
H29: 주식회사 에스에스지닷컴 | I29: other Online malls
H30: 주식회사컬리 | I30: other Online malls
H31: (주)더블유컨셉코리아 | I31: other Online malls
H32: 오늘의집 | I32: other Online malls
H33: (주)카카오 : 선물하기 | I33: other Online malls
H34: (주)이베이코리아(옥션) | I34: other Online malls
H35: 십일번가 주식회사 | I35: other Online malls
H36: (주)카카오 : 톡스토어 | I36: other Online malls
H37: 카페24 주식회사 | I37: other Online malls
H38: G-market | I38: other Online malls
H39: 씨제이홈쇼핑_ TVHS | I39: TVHS

Sheet Sales_Plan
A1: Period Type | B1: Month | C1: Week Start | D1: Week End | E1: Metric | F1: Channel | G1: Retailer | H1: Scenario | I1: Currency | J1: Value
A2: Monthly | B2: 2026-09 | E2: NS | F2: Total | G2: Total | H2: IBP | I2: USD | J2: 12020000
A3: Monthly | B3: 2026-09 | E3: NS | F3: Total | G3: Total | H3: LE1 | I3: USD | J3: 7580000
A4: Monthly | B4: 2026-09 | E4: NS | F4: Total | G4: Total | H4: O&R | I4: USD | J4: 720000
A5: Monthly | B5: 2026-09 | E5: NS | F5: Total | G5: Total | H5: LE2 | I5: USD | J5: 8340000
A6: Monthly | B6: 2026-09 | E6: NS | F6: Online | G6: Online Total | H6: IBP | I6: USD | J6: 6450000
A7: Monthly | B7: 2026-09 | E7: NS | F7: Online | G7: Online Total | H7: LE1 | I7: USD | J7: 3770000
A8: Monthly | B8: 2026-09 | E8: NS | F8: Online | G8: Online Total | H8: O&R | I8: USD | J8: 270000
A9: Monthly | B9: 2026-09 | E9: NS | F9: Online | G9: Online Total | H9: LE2 | I9: USD | J9: 4080000
A10: Monthly | B10: 2026-09 | E10: NS | F10: Online | G10: Coupang | H10: IBP | I10: USD | J10: 2661753
A11: Monthly | B11: 2026-09 | E11: NS | F11: Online | G11: Coupang | H11: LE1 | I11: USD | J11: 989583
A12: Monthly | B12: 2026-09 | E12: NS | F12: Online | G12: Coupang | H12: O&R | I12: USD | J12: 600000
A13: Monthly | B13: 2026-09 | E13: NS | F13: Online | G13: Coupang | H13: LE2 | I13: USD | J13: 1589583
... A59: Monthly | B59: 2026-09 | E59: NS | F59: Offline | G59: Dept Store | H59: LE2 | I59: USD | J59: 356753
A60: Weekly | B60: 2026-09 | C60: 46266 | D60: 46271 | E60: NS | F60: Total | G60: Total | H60: Actual | I60: USD | J60: 920000
A61: Weekly | B61: 2026-09 | C61: 46272 | D61: 46278 | E61: NS | F61: Total | G61: Total | H61: Actual | I61: USD | J61: 1770000
A62: Weekly | B62: 2026-09 | C62: 46279 | D62: 46285 | E62: NS | F62: Total | G62: Total | H62: LE | I62: USD | J62: 2000000
A63: Weekly | B63: 2026-09 | C63: 46286 | D63: 46292 | E63: NS | F63: Total | G63: Total | H63: LE | I63: USD | J63: 1820000
A64: Weekly | B64: 2026-09 | C64: 46293 | D64: 46295 | E64: NS | F64: Total | G64: Total | H64: LE | I64: USD | J64: 1080000
A65: Weekly | B65: 2026-09 | C65: 46266 | D65: 46271 | E65: NS | F65: Online | G65: Coupang | H65: Actual | I65: USD | J65: 150000
A66: Weekly | B66: 2026-09 | C66: 46272 | D66: 46278 | E66: NS | F66: Online | G66: Coupang | H66: Actual | I66: USD | J66: 330000
A67: Weekly | B67: 2026-09 | C67: 46266 | D67: 46271 | E67: NS | F67: Online | G67: Naver | H67: Actual | I67: USD | J67: 160000
A68: Weekly | B68: 2026-09 | C68: 46272 | D68: 46278 | E68: NS | F68: Online | G68: Naver | H68: Actual | I68: USD | J68: 400000
A69: Weekly | B69: 2026-09 | C69: 46266 | D69: 46271 | E69: NS | F69: Online | G69: DTC | H69: Actual | I69: USD | J69: 20000
A70: Weekly | B70: 2026-09 | C70: 46272 | D70: 46278 | E70: NS | F70: Online | G70: DTC | H70: Actual | I70: USD | J70: 50000
A71: Weekly | B71: 2026-09 | C71: 46286 | D71: 46292 | E71: NS | F71: Online | G71: DTC | H71: LE | I71: USD | J71: 50000
... A98: Weekly | B98: 2026-09 | C98: 46272 | D98: 46278 | E98: NS | F98: Offline | G98: Dept Store | H98: Actual | I98: USD | J98: 50000
A99: Monthly | B99: 2026-10 | E99: NS | F99: Total | G99: Total | H99: Target | I99: USD | J99: 14423508
A100: Monthly | B100: 2026-10 | E100: NS | F100: Online | G100: Online Total | H100: Target | I100: USD | J100: 7441780
A101: Monthly | B101: 2026-10 | E101: NS | F101: Online | G101: Coupang | H101: Target | I101: USD | J101: 3049205
A102: Monthly | B102: 2026-10 | E102: NS | F102: Online | G102: Naver | H102: Target | I102: USD | J102: 2032065
A103: Monthly | B103: 2026-10 | E103: NS | F103: Online | G103: DTC | H103: Target | I103: USD | J103: 392873
A104: Monthly | B104: 2026-10 | E104: NS | F104: Online | G104: other Online malls | H104: Target | I104: USD | J104: 358593
A105: Monthly | B105: 2026-10 | E105: NS | F105: Online | G105: Group Buying | H105: Target | I105: USD | J105: 1609044
A106: Monthly | B106: 2026-10 | E106: NS | F106: TVHS | G106: TVHS and PP Total | H106: Target | I106: USD | J106: 2420093
A107: Monthly | B107: 2026-10 | E107: NS | F107: TVHS | G107: TVHS | H107: Target | I107: USD | J107: 2046064
A108: Monthly | B108: 2026-10 | E108: NS | F108: TVHS | G108: PP | H108: Target | I108: USD | J108: 374029
A109: Monthly | B109: 2026-10 | E109: NS | F109: Offline | G109: Offline Total | H109: Target | I109: USD | J109: 4561637
A110: Monthly | B110: 2026-10 | E110: NS | F110: Offline | G110: Costco | H110: Target | I110: USD | J110: 1597034
... A200: Monthly | B200: 2026-12 | E200: NS | F200: Offline | G200: Traders | H200: IBP | I200: USD | J200: 242701.27
